F
======================================================================
FAIL: test_24_concurrent_and_batch_operations (test_gds.GDSTest.test_24_concurrent_and_batch_operations)
测试并发和批量操作
----------------------------------------------------------------------
Traceback (most recent call last):
  File "/Users/wukunhuan/.local/bin/_UNITTEST/test_gds.py", line 312, in _run_gds_command
    self.assertEqual(result.returncode, 0, f"命令执行失败: {command}")
AssertionError: 1 != 0 : 命令执行失败: 'echo "Content 1" > batch_file1.txt'

During handling of the above exception, another exception occurred:

Traceback (most recent call last):
  File "/Users/wukunhuan/.local/bin/_UNITTEST/test_gds.py", line 1999, in test_24_concurrent_and_batch_operations
    result = self._run_gds_command(f'\'echo "Content {i+1}" > {filename}\'')
             ^^^^^^^^^^^^^^^^^^^^^^^^^^^^^^^^^^^^^^^^^^^^^^^^^^^^^^^^^^^^^^^
  File "/Users/wukunhuan/.local/bin/_UNITTEST/test_gds.py", line 318, in _run_gds_command
    self.fail(f"命令执行异常: {command} - {e}")
AssertionError: 命令执行异常: 'echo "Content 1" > batch_file1.txt' - 1 != 0 : 命令执行失败: 'echo "Content 1" > batch_file1.txt'

----------------------------------------------------------------------
Ran 1 test in 179.434s

FAILED (failures=1)
🚀 设置GDS全面测试环境...
📁 远端测试目录: ~/tmp/gds_test_20250831_072436_514232_a48f0913
✅ 已切换到远端测试目录: ~/tmp/gds_test_20250831_072436_514232_a48f0913
📁 本地临时目录: /var/folders/w0/m02j_xv925sg34708rb2xgzr0000gn/T/gds_test_local_dc9y5o_s
✅ 测试环境设置完成

🧪 测试23: 并发和批量操作

🔧 执行命令: 'echo "Content 1" > batch_file1.txt'
📤 返回码: 1
📝 输出: ⏳ Waiting for result ..........√
⏳ Validating file creation ................................✗
文件创建命令成功但验证失败: Path 'batch_file1.txt' not found after 30 verification attempts
...
💥 命令执行异常: 1 != 0 : 命令执行失败: 'echo "Content 1" > batch_file1.txt'
