F
======================================================================
FAIL: test_19_code_execution_scenario (test_gds.GDSTest.test_19_code_execution_scenario)
测试代码执行场景
----------------------------------------------------------------------
Traceback (most recent call last):
  File "/Users/wukunhuan/.local/bin/_UNITTEST/test_gds.py", line 312, in _run_gds_command
    self.assertEqual(result.returncode, 0, f"命令执行失败: {command}")
AssertionError: 1 != 0 : 命令执行失败: mkdir -p test07_project

During handling of the above exception, another exception occurred:

Traceback (most recent call last):
  File "/Users/wukunhuan/.local/bin/_UNITTEST/test_gds.py", line 1534, in test_19_code_execution_scenario
    result = self._run_gds_command('mkdir -p test07_project')
             ^^^^^^^^^^^^^^^^^^^^^^^^^^^^^^^^^^^^^^^^^^^^^^^^
  File "/Users/wukunhuan/.local/bin/_UNITTEST/test_gds.py", line 318, in _run_gds_command
    self.fail(f"命令执行异常: {command} - {e}")
AssertionError: 命令执行异常: mkdir -p test07_project - 1 != 0 : 命令执行失败: mkdir -p test07_project

----------------------------------------------------------------------
Ran 1 test in 187.225s

FAILED (failures=1)
🚀 设置GDS全面测试环境...
📁 远端测试目录: ~/tmp/gds_test_20250831_064349_191197_359c639e
✅ 已切换到远端测试目录: ~/tmp/gds_test_20250831_064349_191197_359c639e
📁 本地临时目录: /var/folders/w0/m02j_xv925sg34708rb2xgzr0000gn/T/gds_test_local_qafdqx8j
✅ 测试环境设置完成

🧪 测试19: 代码执行场景
📦 阶段1: 创建测试项目

🔧 执行命令: mkdir -p test07_project
📤 返回码: 1
📝 输出: ⏳ Waiting for result .........√
⏳ Validating dir creation ..............................................................✗
目录创建可能失败，验证超时: test07_project
...
💥 命令执行异常: 1 != 0 : 命令执行失败: mkdir -p test07_project
