ERROR

======================================================================
ERROR: setUpClass (test_gds.GDSTest)
----------------------------------------------------------------------
Traceback (most recent call last):
  File "/Users/wukunhuan/.local/bin/_UNITTEST/test_gds.py", line 71, in setUpClass
    cls._setup_remote_test_directory()
  File "/Users/wukunhuan/.local/bin/_UNITTEST/test_gds.py", line 104, in _setup_remote_test_directory
    raise RuntimeError(error_msg)
RuntimeError: 创建远端测试目录失败: 返回码=1, stderr=, stdout=Command 'mkdir -p ~/tmp/gds_test_20251013_000420_981733_f110b82f' failed


----------------------------------------------------------------------
Ran 0 tests in 37.561s

FAILED (errors=1)
设置GDS全面测试环境...
远端测试目录: ~/tmp/gds_test_20251013_000420_981733_f110b82f
Warning: 创建远端测试目录失败: 返回码=1, stderr=, stdout=Command 'mkdir -p ~/tmp/gds_test_20251013_000420_981733_f110b82f' failed

