test_14_venv_basic (test_gds.GDSTest) ... /Users/wukunhuan/Library/Python/3.9/lib/python/site-packages/urllib3/__init__.py:35: NotOpenSSLWarning: urllib3 v2 only supports OpenSSL 1.1.1+, currently the 'ssl' module is compiled with 'LibreSSL 2.8.3'. See: https://github.com/urllib3/urllib3/issues/3020
  warnings.warn(
FAIL

======================================================================
FAIL: test_14_venv_basic (test_gds.GDSTest)
----------------------------------------------------------------------
Traceback (most recent call last):
  File "/Users/wukunhuan/.local/bin/_UNITTEST/test_gds.py", line 1703, in test_14_venv_basic
    self.assertIn(venv_name, result.stdout)
AssertionError: 'test_env_1760548058' not found in '\n\x1b[K⏳ Waiting for result ....\n\x1b[K\n\x1b[K'

----------------------------------------------------------------------
Ran 1 test in 115.693s

FAILED (failures=1)
设置GDS全面测试环境...
远端测试目录: ~/tmp/gds_test_20251016_010630_486794_0fe08e4e
已切换到远端测试目录: ~/tmp/gds_test_20251016_010630_486794_0fe08e4e
本地临时目录: /var/folders/w0/m02j_xv925sg34708rb2xgzr0000gn/T/gds_test_local_ymbcrtpp
测试环境设置完成
虚拟环境名称: test_env_1760548058
命令转译成功: venv --create test_env_1760548058 -> venv --create test_env_1760548058
返回码: 0
输出: 
[K⏳ Waiting for result ....
[K
[K...
Warning: 错误: bash: line 1: venv: command not found
...
命令转译成功: venv --list -> venv --list
返回码: 0
输出: 
[K⏳ Waiting for result ....
[K
[K...
Warning: 错误: bash: line 1: venv: command not found
...
